Entering .bash_profile ...
sh: cdo: command not found
ncatted: ERROR file "tmp01.nc" not found. It does not exist on the local filesystem, nor does it match remote filename patterns (e.g., http://foo or foo.bar.edu:file).
ncatted: HINT file-not-found errors usually arise from filename typos, incorrect paths, missing files, or capricious gods. Please verify spelling and location of requested file. If the file resides on a High Performance Storage System (HPSS) accessible via the 'hsi' command, then add the --hpss option and re-try command.
ncks: ERROR file "tmp01.nc" not found. It does not exist on the local filesystem, nor does it match remote filename patterns (e.g., http://foo or foo.bar.edu:file).
ncks: HINT file-not-found errors usually arise from filename typos, incorrect paths, missing files, or capricious gods. Please verify spelling and location of requested file. If the file resides on a High Performance Storage System (HPSS) accessible via the 'hsi' command, then add the --hpss option and re-try command.
Traceback (most recent call last):
  File "/glade/u/apps/opt/conda/envs/npl/lib/python3.10/site-packages/xarray/backends/file_manager.py", line 211, in _acquire_with_cache_info
    file = self._cache[self._key]
  File "/glade/u/apps/opt/conda/envs/npl/lib/python3.10/site-packages/xarray/backends/lru_cache.py", line 56, in __getitem__
    value = self._cache[key]
KeyError: [<class 'netCDF4._netCDF4.Dataset'>, ('/glade/derecho/scratch/lgchen/data/ERA5forSODA/original/netCDF/6hr/tmp02.nc',), 'r', (('clobber', True), ('diskless', False), ('format', 'NETCDF4'), ('persist', False)), '514c8495-061a-4f3c-80b7-f21190c4f063']

During handling of the above exception, another exception occurred:

Traceback (most recent call last):
  File "/glade/work/lgchen/project/SODA3/code_forcing4SODA/forcing4SODA_repo/usingCDSAPI_ERA5/2023/05.ERA5_ChangeAttrTime.py", line 61, in <module>
    ds     = xr.open_dataset('./tmp02.nc')
  File "/glade/u/apps/opt/conda/envs/npl/lib/python3.10/site-packages/xarray/backends/api.py", line 566, in open_dataset
    backend_ds = backend.open_dataset(
  File "/glade/u/apps/opt/conda/envs/npl/lib/python3.10/site-packages/xarray/backends/netCDF4_.py", line 590, in open_dataset
    store = NetCDF4DataStore.open(
  File "/glade/u/apps/opt/conda/envs/npl/lib/python3.10/site-packages/xarray/backends/netCDF4_.py", line 391, in open
    return cls(manager, group=group, mode=mode, lock=lock, autoclose=autoclose)
  File "/glade/u/apps/opt/conda/envs/npl/lib/python3.10/site-packages/xarray/backends/netCDF4_.py", line 338, in __init__
    self.format = self.ds.data_model
  File "/glade/u/apps/opt/conda/envs/npl/lib/python3.10/site-packages/xarray/backends/netCDF4_.py", line 400, in ds
    return self._acquire()
  File "/glade/u/apps/opt/conda/envs/npl/lib/python3.10/site-packages/xarray/backends/netCDF4_.py", line 394, in _acquire
    with self._manager.acquire_context(needs_lock) as root:
  File "/glade/u/apps/opt/conda/envs/npl/lib/python3.10/contextlib.py", line 135, in __enter__
    return next(self.gen)
  File "/glade/u/apps/opt/conda/envs/npl/lib/python3.10/site-packages/xarray/backends/file_manager.py", line 199, in acquire_context
    file, cached = self._acquire_with_cache_info(needs_lock)
  File "/glade/u/apps/opt/conda/envs/npl/lib/python3.10/site-packages/xarray/backends/file_manager.py", line 217, in _acquire_with_cache_info
    file = self._opener(*self._args, **kwargs)
  File "src/netCDF4/_netCDF4.pyx", line 2464, in netCDF4._netCDF4.Dataset.__init__
  File "src/netCDF4/_netCDF4.pyx", line 2027, in netCDF4._netCDF4._ensure_nc_success
FileNotFoundError: [Errno 2] No such file or directory: '/glade/derecho/scratch/lgchen/data/ERA5forSODA/original/netCDF/6hr/tmp02.nc'
